Workbook

Sheet OLP_Scored_Model
A1: SrNo | B1: Emp.Code | C1: Cohort | D1: Name | E1: Org.Unit | F1: Position Text | G1: Job ID | H1: Job Role | I1: H R | J1: HRBP Name | K1: Marital Status | L1: DOJ | M1: Age (YY.MM) | N1: DOB | O1: Current Grade | P1: Current Designation | Q1: RilExp YY.MM | R1: Prev Exp YY.MM | S1: Tot Exp YY.MM | T1: DOL PROM | U1: DOL PROGRESSION | V1: RTG21-22 | W1: RTG22-23 | X1: RTG23-24 | Y1: RTG24-25 | Z1: RTG25-26 | AA1: Qualification | AB1: Prev Exp Clean | AC1: Age Clean | AD1: RilExp Clean | AE1: Tot Exp Clean | AF1: RTG21-22_num | AG1: RTG22-23_num | AH1: RTG23-24_num | AI1: RTG24-25_num | AJ1: RTG25-26_num | AK1: avg_rating | AL1: rating_trend | AM1: rating_consistency | AN1: recency_weighted_rtg | AO1: age_group | AP1: seniority_tier | AQ1: was_promoted | AR1: had_progression | AS1: score_avg_rating | AT1: score_trend | AU1: score_consistency | AV1: score_exp | AW1: score_recency_rtg | AX1: score_promotion | AY1: score_progression | AZ1: composite_score | BA1: performance_tier | BB1: is_top_performer | BC1: trend_shifted (helper) | BD1: rating_consistency_filled (helper) | BE1: consistency_transformed (helper)
A2: 909 | B2: 55159907 | C2: IT Infrastructure | D2: Mr. Rammohan Kordale | E2: Groupwide Common IT Teams | F2: Head Grp Enterprise IT | G2: 24281719 | H2: Chief Engineering & Tech | I2: Bharat Bhushan | J2: Mr. Bharat Bhushan | K2: Marrd. | L2: 46062 | M2: 59.2 | N2: 24552 | O2: Exe.Vice President | P2: Executive Vice-President | Q2: .3 | R2: 9.4 | S2: 9.7 | AA2: SSC/XTH STD/SSLC-Upper Primary Education-1982(FT) | AB2: =IFERROR(VALUE(R2),0) -> 9.4 | AC2: =IFERROR(VALUE(M2),"") -> 59.2 | AD2: =IFERROR(VALUE(Q2),"") -> 0.3 | AE2: =IFERROR(VALUE(S2),"") -> 9.7 | AF2: =IF(V2="","",VLOOKUP(V2,Assumptions!$B$6:$C$9,2,FALSE())) | AG2: =IF(W2="","",VLOOKUP(W2,Assumptions!$B$6:$C$9,2,FALSE())) | AH2: =IF(X2="","",VLOOKUP(X2,Assumptions!$B$6:$C$9,2,FALSE())) | AI2: =IF(Y2="","",VLOOKUP(Y2,Assumptions!$B$6:$C$9,2,FALSE())) | AJ2: =IF(Z2="","",VLOOKUP(Z2,Assumptions!$B$6:$C$9,2,FALSE())) | AK2: =IFERROR(ROUND(AVERAGE(AF2:AJ2),3),"") | AL2: =IF(OR(AF2="",AJ2=""),"",AJ2-AF2) | AM2: =IF(COUNT(AF2:AJ2)>=2,ROUND(_xlfn.STDEV.S(AF2:AJ2),3),"") | AN2: =ROUND((IF(AF2="",0,AF2)*Assumptions!$F$15)+(IF(AG2="",0,AG2)*Assumptions!$F$16)+(IF(AH2="",0,AH2)*Assumptions!$F$17)+(IF(AI2="",0,AI2)*Assumptions!$F$18)+(IF(AJ2="",0,AJ2)*Assumptions!$F$19),3) -> 0 | AO2: =IF(AC2<=20,"",IF(AC2<=Assumptions!$F$6,"20-30",IF(AC2<=Assumptions!$F$7,"30-40",IF(AC2<=Assumptions!$F$8,"40-50",IF(AC2<=Assumptions!$F$9,"50-60",IF(AC2<=Assumptions!$F$10,"60+","")))))) -> 50-60 | AP2: =IFERROR(VLOOKUP(O2,Assumptions!$B$14:$C$26,2,FALSE()),"Other") -> Leadership | AQ2: =IF(T2="",0,1) -> 0 | AR2: =IF(U2="",0,1) -> 0 | AS2: =IF(AK2="","",IF(MAX($AK$2:$AK$921)=MIN($AK$2:$AK$921),50,ROUND((AK2-MIN($AK$2:$AK$921))/(MAX($AK$2:$AK$921)-MIN($AK$2:$AK$921))*100,2))) | AT2: =IF(MAX($BC$2:$BC$921)=MIN($BC$2:$BC$921),50,ROUND((BC2-MIN($BC$2:$BC$921))/(MAX($BC$2:$BC$921)-MIN($BC$2:$BC$921))*100,2)) -> 50 | AU2: =IF(MAX($BE$2:$BE$921)=MIN($BE$2:$BE$921),50,ROUND((BE2-MIN($BE$2:$BE$921))/(MAX($BE$2:$BE$921)-MIN($BE$2:$BE$921))*100,2)) -> 75.4 | AV2: =IF(MAX($AD$2:$AD$921)=MIN($AD$2:$AD$921),50,ROUND((AD2-MIN($AD$2:$AD$921))/(MAX($AD$2:$AD$921)-MIN($AD$2:$AD$921))*100,2)) -> 0.52 | AW2: =IF(MAX($AN$2:$AN$921)=MIN($AN$2:$AN$921),50,ROUND((AN2-MIN($AN$2:$AN$921))/(MAX($AN$2:$AN$921)-MIN($AN$2:$AN$921))*100,2)) -> 0 | AX2: =AQ2*100 -> 0 | AY2: =AR2*100 -> 0 | AZ2: =IFERROR(ROUND(AS2*Assumptions!$I$6+AW2*Assumptions!$I$7+AT2*Assumptions!$I$8+AU2*Assumptions!$I$9+AV2*Assumptions!$I$10+AX2*Assumptions!$I$11+AY2*Assumptions!$I$12,2),"") | BA2: =IF(AZ2="","",IF(AZ2<=Assumptions!$I$18,"Below Expectation",IF(AZ2<=Assumptions!$I$19,"Developing",IF(AZ2<=Assumptions!$I$20,"Meets Expectation",IF(AZ2<=Assumptions!$I$21,"Exceeds","Star Performer"))))) | BB2: =IF(AZ2="",0,IF(AZ2>=Assumptions!$I$26,1,0)) -> 0 | BC2: =IF(AL2="",2,AL2+2) -> 2 | BD2: =IF(AM2="",ROUND(AVERAGE($AM$2:$AM$921),3),AM2) -> 0.426 | BE2: =1-BD2 -> 0.574
A3: 26 | B3: 1128301 | C3: DD&P E&M IT | D3: Mr. Arindam Banerjee | E3: DD&P E&M IT | F3: CIO - DD&P E&M | G3: 24281719 | H3: Chief Engineering & Tech | I3: Bharat Bhushan | J3: Mr. Hemant Jain | K3: Marrd. | L3: 35362 | M3: 58.4 | N3: 24863 | O3: Sr.Vice President | P3: Sr. Vice - President | Q3: 29.7 | R3: 4.5 | S3: 34.0 | T3: 39173 | U3: 44440 | V3: A* | W3: A* | X3: A* | Y3: A* | Z3: A* | AA3: Certificate Course-Others-2009,Gr CWA-Costing-1991,BSc-Chemistry-1988 | AB3: =IFERROR(VALUE(R3),0) -> 4.5 | AC3: =IFERROR(VALUE(M3),"") -> 58.4 | AD3: =IFERROR(VALUE(Q3),"") -> 29.7 | AE3: =IFERROR(VALUE(S3),"") -> 34 | AF3: =IF(V3="","",VLOOKUP(V3,Assumptions!$B$6:$C$9,2,FALSE())) -> 4 | AG3: =IF(W3="","",VLOOKUP(W3,Assumptions!$B$6:$C$9,2,FALSE())) -> 4 | AH3: =IF(X3="","",VLOOKUP(X3,Assumptions!$B$6:$C$9,2,FALSE())) -> 4 | AI3: =IF(Y3="","",VLOOKUP(Y3,Assumptions!$B$6:$C$9,2,FALSE())) -> 4 | AJ3: =IF(Z3="","",VLOOKUP(Z3,Assumptions!$B$6:$C$9,2,FALSE())) -> 4 | AK3: =IFERROR(ROUND(AVERAGE(AF3:AJ3),3),"") -> 4 | AL3: =IF(OR(AF3="",AJ3=""),"",AJ3-AF3) -> 0 | AM3: =IF(COUNT(AF3:AJ3)>=2,ROUND(_xlfn.STDEV.S(AF3:AJ3),3),"") -> 0 | AN3: =ROUND((IF(AF3="",0,AF3)*Assumptions!$F$15)+(IF(AG3="",0,AG3)*Assumptions!$F$16)+(IF(AH3="",0,AH3)*Assumptions!$F$17)+(IF(AI3="",0,AI3)*Assumptions!$F$18)+(IF(AJ3="",0,AJ3)*Assumptions!$F$19),3) -> 4 | AO3: =IF(AC3<=20,"",IF(AC3<=Assumptions!$F$6,"20-30",IF(AC3<=Assumptions!$F$7,"30-40",IF(AC3<=Assumptions!$F$8,"40-50",IF(AC3<=Assumptions!$F$9,"50-60",IF(AC3<=Assumptions!$F$10,"60+","")))))) -> 50-60 | AP3: =IFERROR(VLOOKUP(O3,Assumptions!$B$14:$C$26,2,FALSE()),"Other") -> Leadership | AQ3: =IF(T3="",0,1) -> 1 | AR3: =IF(U3="",0,1) -> 1 | AS3: =IF(AK3="","",IF(MAX($AK$2:$AK$921)=MIN($AK$2:$AK$921),50,ROUND((AK3-MIN($AK$2:$AK$921))/(MAX($AK$2:$AK$921)-MIN($AK$2:$AK$921))*100,2))) -> 100 | AT3: =IF(MAX($BC$2:$BC$921)=MIN($BC$2:$BC$921),50,ROUND((BC3-MIN($BC$2:$BC$921))/(MAX($BC$2:$BC$921)-MIN($BC$2:$BC$921))*100,2)) -> 50 | AU3: =IF(MAX($BE$2:$BE$921)=MIN($BE$2:$BE$921),50,ROUND((BE3-MIN($BE$2:$BE$921))/(MAX($BE$2:$BE$921)-MIN($BE$2:$BE$921))*100,2)) -> 100 | AV3: =IF(MAX($AD$2:$AD$921)=MIN($AD$2:$AD$921),50,ROUND((AD3-MIN($AD$2:$AD$921))/(MAX($AD$2:$AD$921)-MIN($AD$2:$AD$921))*100,2)) -> 80.43 | AW3: =IF(MAX($AN$2:$AN$921)=MIN($AN$2:$AN$921),50,ROUND((AN3-MIN($AN$2:$AN$921))/(MAX($AN$2:$AN$921)-MIN($AN$2:$AN$921))*100,2)) -> 100 | AX3: =AQ3*100 -> 100 | AY3: =AR3*100 -> 100 | AZ3: =IFERROR(ROUND(AS3*Assumptions!$I$6+AW3*Assumptions!$I$7+AT3*Assumptions!$I$8+AU3*Assumptions!$I$9+AV3*Assumptions!$I$10+AX3*Assumptions!$I$11+AY3*Assumptions!$I$12,2),"") -> 90.54 | BA3: =IF(AZ3="","",IF(AZ3<=Assumptions!$I$18,"Below Expectation",IF(AZ3<=Assumptions!$I$19,"Developing",IF(AZ3<=Assumptions!$I$20,"Meets Expectation",IF(AZ3<=Assumptions!$I$21,"Exceeds","Star Performer"))))) -> Star Performer | BB3: =IF(AZ3="",0,IF(AZ3>=Assumptions!$I$26,1,0)) -> 1 | BC3: =IF(AL3="",2,AL3+2) -> 2 | BD3: =IF(AM3="",ROUND(AVERAGE($AM$2:$AM$921),3),AM3) -> 0 | BE3: =1-BD3 -> 1
A4: 30 | B4: 2044308 | C4: Enterprise Application Management | D4: Mr. Rajesh P Sarda | E4: E&M IT SAP Tech Ops | F4: Chief Engineering & Tech | G4: 24281719 | H4: Chief Engineering & Tech | I4: Bharat Bhushan | J4: Mr. Hemant Jain | K4: Marrd. | L4: 35387 | M4: 52.11 | N4: 26836 | O4: Vice President | P4: Vice - President | Q4: 29.6 | R4: .5 | S4: 29.11 | T4: 40269 | U4: 44440 | V4: A* | W4: A* | X4: A* | Y4: A* | Z4: A* | AA4: Management Development Prog : Level - 1-Others-2009,MCA-Computer Applications-1996,BSc-Statistics-1993 | AB4: =IFERROR(VALUE(R4),0) -> 0.5 | AC4: =IFERROR(VALUE(M4),"") -> 52.11 | AD4: =IFERROR(VALUE(Q4),"") -> 29.6 | AE4: =IFERROR(VALUE(S4),"") -> 29.11 | AF4: =IF(V4="","",VLOOKUP(V4,Assumptions!$B$6:$C$9,2,FALSE())) -> 4 | AG4: =IF(W4="","",VLOOKUP(W4,Assumptions!$B$6:$C$9,2,FALSE())) -> 4 | AH4: =IF(X4="","",VLOOKUP(X4,Assumptions!$B$6:$C$9,2,FALSE())) -> 4 | AI4: =IF(Y4="","",VLOOKUP(Y4,Assumptions!$B$6:$C$9,2,FALSE())) -> 4 | AJ4: =IF(Z4="","",VLOOKUP(Z4,Assumptions!$B$6:$C$9,2,FALSE())) -> 4 | AK4: =IFERROR(ROUND(AVERAGE(AF4:AJ4),3),"") -> 4 | AL4: =IF(OR(AF4="",AJ4=""),"",AJ4-AF4) -> 0 | AM4: =IF(COUNT(AF4:AJ4)>=2,ROUND(_xlfn.STDEV.S(AF4:AJ4),3),"") -> 0 | AN4: =ROUND((IF(AF4="",0,AF4)*Assumptions!$F$15)+(IF(AG4="",0,AG4)*Assumptions!$F$16)+(IF(AH4="",0,AH4)*Assumptions!$F$17)+(IF(AI4="",0,AI4)*Assumptions!$F$18)+(IF(AJ4="",0,AJ4)*Assumptions!$F$19),3) -> 4 | AO4: =IF(AC4<=20,"",IF(AC4<=Assumptions!$F$6,"20-30",IF(AC4<=Assumptions!$F$7,"30-40",IF(AC4<=Assumptions!$F$8,"40-50",IF(AC4<=Assumptions!$F$9,"50-60",IF(AC4<=Assumptions!$F$10,"60+","")))))) -> 50-60 | AP4: =IFERROR(VLOOKUP(O4,Assumptions!$B$14:$C$26,2,FALSE()),"Other") -> Leadership | AQ4: =IF(T4="",0,1) -> 1 | AR4: =IF(U4="",0,1) -> 1 | AS4: =IF(AK4="","",IF(MAX($AK$2:$AK$921)=MIN($AK$2:$AK$921),50,ROUND((AK4-MIN($AK$2:$AK$921))/(MAX($AK$2:$AK$921)-MIN($AK$2:$AK$921))*100,2))) -> 100 | AT4: =IF(MAX($BC$2:$BC$921)=MIN($BC$2:$BC$921),50,ROUND((BC4-MIN($BC$2:$BC$921))/(MAX($BC$2:$BC$921)-MIN($BC$2:$BC$921))*100,2)) -> 50 | AU4: =IF(MAX($BE$2:$BE$921)=MIN($BE$2:$BE$921),50,ROUND((BE4-MIN($BE$2:$BE$921))/(MAX($BE$2:$BE$921)-MIN($BE$2:$BE$921))*100,2)) -> 100 | AV4: =IF(MAX($AD$2:$AD$921)=MIN($AD$2:$AD$921),50,ROUND((AD4-MIN($AD$2:$AD$921))/(MAX($AD$2:$AD$921)-MIN($AD$2:$AD$921))*100,2)) -> 80.16 | AW4: =IF(MAX($AN$2:$AN$921)=MIN($AN$2:$AN$921),50,ROUND((AN4-MIN($AN$2:$AN$921))/(MAX($AN$2:$AN$921)-MIN($AN$2:$AN$921))*100,2)) -> 100 | AX4: =AQ4*100 -> 100 | AY4: =AR4*100 -> 100 | AZ4: =IFERROR(ROUND(AS4*Assumptions!$I$6+AW4*Assumptions!$I$7+AT4*Assumptions!$I$8+AU4*Assumptions!$I$9+AV4*Assumptions!$I$10+AX4*Assumptions!$I$11+AY4*Assumptions!$I$12,2),"") -> 90.52 | BA4: =IF(AZ4="","",IF(AZ4<=Assumptions!$I$18,"Below Expectation",IF(AZ4<=Assumptions!$I$19,"Developing",IF(AZ4<=Assumptions!$I$20,"Meets Expectation",IF(AZ4<=Assumptions!$I$21,"Exceeds","Star Performer"))))) -> Star Performer | BB4: =IF(AZ4="",0,IF(AZ4>=Assumptions!$I$26,1,0)) -> 1 | BC4: =IF(AL4="",2,AL4+2) -> 2 | BD4: =IF(AM4="",ROUND(AVERAGE($AM$2:$AM$921),3),AM4) -> 0 | BE4: =1-BD4 -> 1
A5: 9 | B5: 25514 | C5: IT Infrastructure | D5: Mr. Kamal Joshi | E5: Video Conferencing | F5: Chief - IT Infrastructure | G5: 24281819 | H5: Chief IT Infrastructure | I5: Bharat Bhushan | J5: Ms. Sudeshna Das | K5: Marrd. | L5: 35735 | M5: 55.10 | N5: 25779 | O5: Vice President | P5: Vice - President | Q5: 28.7 | R5: 3.2 | S5: 31.9 | T5: 40269 | U5: 44470 | V5: A* | W5: A* | X5: A* | Y5: A* | Z5: A* | AA5: Diploma - Engineering-Industrial Electronics-1992(FT) | AB5: =IFERROR(VALUE(R5),0) -> 3.2 | AC5: =IFERROR(VALUE(M5),"") -> 55.1 | AD5: =IFERROR(VALUE(Q5),"") -> 28.7 | AE5: =IFERROR(VALUE(S5),"") -> 31.9 | AF5: =IF(V5="","",VLOOKUP(V5,Assumptions!$B$6:$C$9,2,FALSE())) -> 4 | AG5: =IF(W5="","",VLOOKUP(W5,Assumptions!$B$6:$C$9,2,FALSE())) -> 4 | AH5: =IF(X5="","",VLOOKUP(X5,Assumptions!$B$6:$C$9,2,FALSE())) -> 4 | AI5: =IF(Y5="","",VLOOKUP(Y5,Assumptions!$B$6:$C$9,2,FALSE())) -> 4 | AJ5: =IF(Z5="","",VLOOKUP(Z5,Assumptions!$B$6:$C$9,2,FALSE())) -> 4 | AK5: =IFERROR(ROUND(AVERAGE(AF5:AJ5),3),"") -> 4 | AL5: =IF(OR(AF5="",AJ5=""),"",AJ5-AF5) -> 0 | AM5: =IF(COUNT(AF5:AJ5)>=2,ROUND(_xlfn.STDEV.S(AF5:AJ5),3),"") -> 0 | AN5: =ROUND((IF(AF5="",0,AF5)*Assumptions!$F$15)+(IF(AG5="",0,AG5)*Assumptions!$F$16)+(IF(AH5="",0,AH5)*Assumptions!$F$17)+(IF(AI5="",0,AI5)*Assumptions!$F$18)+(IF(AJ5="",0,AJ5)*Assumptions!$F$19),3) -> 4 | AO5: =IF(AC5<=20,"",IF(AC5<=Assumptions!$F$6,"20-30",IF(AC5<=Assumptions!$F$7,"30-40",IF(AC5<=Assumptions!$F$8,"40-50",IF(AC5<=Assumptions!$F$9,"50-60",IF(AC5<=Assumptions!$F$10,"60+","")))))) -> 50-60 | AP5: =IFERROR(VLOOKUP(O5,Assumptions!$B$14:$C$26,2,FALSE()),"Other") -> Leadership | AQ5: =IF(T5="",0,1) -> 1 | AR5: =IF(U5="",0,1) -> 1 | AS5: =IF(AK5="","",IF(MAX($AK$2:$AK$921)=MIN($AK$2:$AK$921),50,ROUND((AK5-MIN($AK$2:$AK$921))/(MAX($AK$2:$AK$921)-MIN($AK$2:$AK$921))*100,2))) -> 100 | AT5: =IF(MAX($BC$2:$BC$921)=MIN($BC$2:$BC$921),50,ROUND((BC5-MIN($BC$2:$BC$921))/(MAX($BC$2:$BC$921)-MIN($BC$2:$BC$921))*100,2)) -> 50 | AU5: =IF(MAX($BE$2:$BE$921)=MIN($BE$2:$BE$921),50,ROUND((BE5-MIN($BE$2:$BE$921))/(MAX($BE$2:$BE$921)-MIN($BE$2:$BE$921))*100,2)) -> 100 | AV5: =IF(MAX($AD$2:$AD$921)=MIN($AD$2:$AD$921),50,ROUND((AD5-MIN($AD$2:$AD$921))/(MAX($AD$2:$AD$921)-MIN($AD$2:$AD$921))*100,2)) -> 77.71 | AW5: =IF(MAX($AN$2:$AN$921)=MIN($AN$2:$AN$921),50,ROUND((AN5-MIN($AN$2:$AN$921))/(MAX($AN$2:$AN$921)-MIN($AN$2:$AN$921))*100,2)) -> 100 | AX5: =AQ5*100 -> 100 | AY5: =AR5*100 -> 100 | AZ5: =IFERROR(ROUND(AS5*Assumptions!$I$6+AW5*Assumptions!$I$7+AT5*Assumptions!$I$8+AU5*Assumptions!$I$9+AV5*Assumptions!$I$10+AX5*Assumptions!$I$11+AY5*Assumptions!$I$12,2),"") -> 90.27 | BA5: =IF(AZ5="","",IF(AZ5<=Assumptions!$I$18,"Below Expectation",IF(AZ5<=Assumptions!$I$19,"Developing",IF(AZ5<=Assumptions!$I$20,"Meets Expectation",IF(AZ5<=Assumptions!$I$21,"Exceeds","Star Performer"))))) -> Star Performer | BB5: =IF(AZ5="",0,IF(AZ5>=Assumptions!$I$26,1,0)) -> 1 | BC5: =IF(AL5="",2,AL5+2) -> 2 | BD5: =IF(AM5="",ROUND(AVERAGE($AM$2:$AM$921),3),AM5) -> 0 | BE5: =1-BD5 -> 1
A6: 10 | B6: 33214 | C6: JioCX | D6: Mr. Vikramsingh V Mohite | E6: JioCX Engineering | F6: Head Software Developer JioCX | G6: 24281770 | H6: Chief Software Development | I6: Bharat Bhushan | J6: Ms. Arya Khamparia | K6: Marrd. | L6: 35977 | M6: 51.0 | N6: 27546 | O6: Vice President | P6: Vice - President | Q6: 27.11 | R6: . | S6: 27.11 | T6: 40269 | U6: 44652 | V6: A* | W6: A* | X6: A* | Y6: A* | Z6: A* | AA6: BE-Electronics Engg-1996(FT) | AB6: =IFERROR(VALUE(R6),0) -> 0 | AC6: =IFERROR(VALUE(M6),"") -> 51 | AD6: =IFERROR(VALUE(Q6),"") -> 27.11 | AE6: =IFERROR(VALUE(S6),"") -> 27.11 | AF6: =IF(V6="","",VLOOKUP(V6,Assumptions!$B$6:$C$9,2,FALSE())) -> 4 | AG6: =IF(W6="","",VLOOKUP(W6,Assumptions!$B$6:$C$9,2,FALSE())) -> 4 | AH6: =IF(X6="","",VLOOKUP(X6,Assumptions!$B$6:$C$9,2,FALSE())) -> 4 | AI6: =IF(Y6="","",VLOOKUP(Y6,Assumptions!$B$6:$C$9,2,FALSE())) -> 4 | AJ6: =IF(Z6="","",VLOOKUP(Z6,Assumptions!$B$6:$C$9,2,FALSE())) -> 4 | AK6: =IFERROR(ROUND(AVERAGE(AF6:AJ6),3),"") -> 4 | AL6: =IF(OR(AF6="",AJ6=""),"",AJ6-AF6) -> 0 | AM6: =IF(COUNT(AF6:AJ6)>=2,ROUND(_xlfn.STDEV.S(AF6:AJ6),3),"") -> 0 | AN6: =ROUND((IF(AF6="",0,AF6)*Assumptions!$F$15)+(IF(AG6="",0,AG6)*Assumptions!$F$16)+(IF(AH6="",0,AH6)*Assumptions!$F$17)+(IF(AI6="",0,AI6)*Assumptions!$F$18)+(IF(AJ6="",0,AJ6)*Assumptions!$F$19),3) -> 4 | AO6: =IF(AC6<=20,"",IF(AC6<=Assumptions!$F$6,"20-30",IF(AC6<=Assumptions!$F$7,"30-40",IF(AC6<=Assumptions!$F$8,"40-50",IF(AC6<=Assumptions!$F$9,"50-60",IF(AC6<=Assumptions!$F$10,"60+","")))))) -> 50-60 | AP6: =IFERROR(VLOOKUP(O6,Assumptions!$B$14:$C$26,2,FALSE()),"Other") -> Leadership | AQ6: =IF(T6="",0,1) -> 1 | AR6: =IF(U6="",0,1) -> 1 | AS6: =IF(AK6="","",IF(MAX($AK$2:$AK$921)=MIN($AK$2:$AK$921),50,ROUND((AK6-MIN($AK$2:$AK$921))/(MAX($AK$2:$AK$921)-MIN($AK$2:$AK$921))*100,2))) -> 100 | AT6: =IF(MAX($BC$2:$BC$921)=MIN($BC$2:$BC$921),50,ROUND((BC6-MIN($BC$2:$BC$921))/(MAX($BC$2:$BC$921)-MIN($BC$2:$BC$921))*100,2)) -> 50 | AU6: =IF(MAX($BE$2:$BE$921)=MIN($BE$2:$BE$921),50,ROUND((BE6-MIN($BE$2:$BE$921))/(MAX($BE$2:$BE$921)-MIN($BE$2:$BE$921))*100,2)) -> 100 | AV6: =IF(MAX($AD$2:$AD$921)=MIN($AD$2:$AD$921),50,ROUND((AD6-MIN($AD$2:$AD$921))/(MAX($AD$2:$AD$921)-MIN($AD$2:$AD$921))*100,2)) -> 73.39 | AW6: =IF(MAX($AN$2:$AN$921)=MIN($AN$2:$AN$921),50,ROUND((AN6-MIN($AN$2:$AN$921))/(MAX($AN$2:$AN$921)-MIN($AN$2:$AN$921))*100,2)) -> 100 | AX6: =AQ6*100 -> 100 | AY6: =AR6*100 -> 100 | AZ6: =IFERROR(ROUND(AS6*Assumptions!$I$6+AW6*Assumptions!$I$7+AT6*Assumptions!$I$8+AU6*Assumptions!$I$9+AV6*Assumptions!$I$10+AX6*Assumptions!$I$11+AY6*Assumptions!$I$12,2),"") -> 89.84 | BA6: =IF(AZ6="","",IF(AZ6<=Assumptions!$I$18,"Below Expectation",IF(AZ6<=Assumptions!$I$19,"Developing",IF(AZ6<=Assumptions!$I$20,"Meets Expectation",IF(AZ6<=Assumptions!$I$21,"Exceeds","Star Performer"))))) -> Star Performer | BB6: =IF(AZ6="",0,IF(AZ6>=Assumptions!$I$26,1,0)) -> 1 | BC6: =IF(AL6="",2,AL6+2) -> 2 | BD6: =IF(AM6="",ROUND(AVERAGE($AM$2:$AM$921),3),AM6) -> 0 | BE6: =1-BD6 -> 1
A7: 13 | B7: 39214 | C7: JioCX | D7: Mr. Shashikant R Kadam | E7: JioCX Engineering | F7: Head Devops Engineer JioCX | G7: 24281802 | H7: Head SRE | I7: Bharat Bhushan | J7: Ms. Arya Khamparia | K7: Marrd. | L7: 36810 | M7: 47.8 | N7: 28762 | O7: Asst. Vice President | P7: Asst. Vice - President | Q7: 25.7 | R7: . | S7: 25.7 | T7: 40269 | U7: 43191 | V7: A* | W7: A* | X7: A* | Y7: A* | Z7: A* | AA7: BE-Electronics Engg-2000 | AB7: =IFERROR(VALUE(R7),0) -> 0 | AC7: =IFERROR(VALUE(M7),"") -> 47.8 | AD7: =IFERROR(VALUE(Q7),"") -> 25.7 | AE7: =IFERROR(VALUE(S7),"") -> 25.7 | AF7: =IF(V7="","",VLOOKUP(V7,Assumptions!$B$6:$C$9,2,FALSE())) -> 4 | AG7: =IF(W7="","",VLOOKUP(W7,Assumptions!$B$6:$C$9,2,FALSE())) -> 4 | AH7: =IF(X7="","",VLOOKUP(X7,Assumptions!$B$6:$C$9,2,FALSE())) -> 4 | AI7: =IF(Y7="","",VLOOKUP(Y7,Assumptions!$B$6:$C$9,2,FALSE())) -> 4 | AJ7: =IF(Z7="","",VLOOKUP(Z7,Assumptions!$B$6:$C$9,2,FALSE())) -> 4 | AK7: =IFERROR(ROUND(AVERAGE(AF7:AJ7),3),"") -> 4 | AL7: =IF(OR(AF7="",AJ7=""),"",AJ7-AF7) -> 0 | AM7: =IF(COUNT(AF7:AJ7)>=2,ROUND(_xlfn.STDEV.S(AF7:AJ7),3),"") -> 0 | AN7: =ROUND((IF(AF7="",0,AF7)*Assumptions!$F$15)+(IF(AG7="",0,AG7)*Assumptions!$F$16)+(IF(AH7="",0,AH7)*Assumptions!$F$17)+(IF(AI7="",0,AI7)*Assumptions!$F$18)+(IF(AJ7="",0,AJ7)*Assumptions!$F$19),3) -> 4 | AO7: =IF(AC7<=20,"",IF(AC7<=Assumptions!$F$6,"20-30",IF(AC7<=Assumptions!$F$7,"30-40",IF(AC7<=Assumptions!$F$8,"40-50",IF(AC7<=Assumptions!$F$9,"50-60",IF(AC7<=Assumptions!$F$10,"60+","")))))) -> 40-50 | AP7: =IFERROR(VLOOKUP(O7,Assumptions!$B$14:$C$26,2,FALSE()),"Other") -> Leadership | AQ7: =IF(T7="",0,1) -> 1 | AR7: =IF(U7="",0,1) -> 1 | AS7: =IF(AK7="","",IF(MAX($AK$2:$AK$921)=MIN($AK$2:$AK$921),50,ROUND((AK7-MIN($AK$2:$AK$921))/(MAX($AK$2:$AK$921)-MIN($AK$2:$AK$921))*100,2))) -> 100 | AT7: =IF(MAX($BC$2:$BC$921)=MIN($BC$2:$BC$921),50,ROUND((BC7-MIN($BC$2:$BC$921))/(MAX($BC$2:$BC$921)-MIN($BC$2:$BC$921))*100,2)) -> 50 | AU7: =IF(MAX($BE$2:$BE$921)=MIN($BE$2:$BE$921),50,ROUND((BE7-MIN($BE$2:$BE$921))/(MAX($BE$2:$BE$921)-MIN($BE$2:$BE$921))*100,2)) -> 100 | AV7: =IF(MAX($AD$2:$AD$921)=MIN($AD$2:$AD$921),50,ROUND((AD7-MIN($AD$2:$AD$921))/(MAX($AD$2:$AD$921)-MIN($AD$2:$AD$921))*100,2)) -> 69.56 | AW7: =IF(MAX($AN$2:$AN$921)=MIN($AN$2:$AN$921),50,ROUND((AN7-MIN($AN$2:$AN$921))/(MAX($AN$2:$AN$921)-MIN($AN$2:$AN$921))*100,2)) -> 100 | AX7: =AQ7*100 -> 100 | AY7: =AR7*100 -> 100 | AZ7: =IFERROR(ROUND(AS7*Assumptions!$I$6+AW7*Assumptions!$I$7+AT7*Assumptions!$I$8+AU7*Assumptions!$I$9+AV7*Assumptions!$I$10+AX7*Assumptions!$I$11+AY7*Assumptions!$I$12,2),"") -> 89.46 | BA7: =IF(AZ7="","",IF(AZ7<=Assumptions!$I$18,"Below Expectation",IF(AZ7<=Assumptions!$I$19,"Developing",IF(AZ7<=Assumptions!$I$20,"Meets Expectation",IF(AZ7<=Assumptions!$I$21,"Exceeds","Star Performer"))))) -> Star Performer | BB7: =IF(AZ7="",0,IF(AZ7>=Assumptions!$I$26,1,0)) -> 1 | BC7: =IF(AL7="",2,AL7+2) -> 2 | BD7: =IF(AM7="",ROUND(AVERAGE($AM$2:$AM$921),3),AM7) -> 0 | BE7: =1-BD7 -> 1
A8: 45 | B8: 10009823 | C8: JioCX | D8: Mr. Saket Gadkari | E8: JioCX Revenue & Customer Success | F8: Chief Revenue | G8: 45282214 | H8: Lead Business Development | I8: Bharat Bhushan | J8: Ms. Arya Khamparia | K8: Marrd. | L8: 37547 | M8: 46.6 | N8: 29184 | O8: Vice President | P8: Vice - President | Q8: 23.7 | R8: 1 | S8: 24.7 | T8: 42461 | U8: 44562 | V8: A* | W8: A* | X8: A* | Y8: A* | Z8: A* | AA8: MBA-Others-2007(PT),BE-Instrumentation-2001(FT) | AB8: =IFERROR(VALUE(R8),0) -> 1 | AC8: =IFERROR(VALUE(M8),"") -> 46.6 | AD8: =IFERROR(VALUE(Q8),"") -> 23.7 | AE8: =IFERROR(VALUE(S8),"") -> 24.7 | AF8: =IF(V8="","",VLOOKUP(V8,Assumptions!$B$6:$C$9,2,FALSE())) -> 4 | AG8: =IF(W8="","",VLOOKUP(W8,Assumptions!$B$6:$C$9,2,FALSE())) -> 4 | AH8: =IF(X8="","",VLOOKUP(X8,Assumptions!$B$6:$C$9,2,FALSE())) -> 4 | AI8: =IF(Y8="","",VLOOKUP(Y8,Assumptions!$B$6:$C$9,2,FALSE())) -> 4 | AJ8: =IF(Z8="","",VLOOKUP(Z8,Assumptions!$B$6:$C$9,2,FALSE())) -> 4 | AK8: =IFERROR(ROUND(AVERAGE(AF8:AJ8),3),"") -> 4 | AL8: =IF(OR(AF8="",AJ8=""),"",AJ8-AF8) -> 0 | AM8: =IF(COUNT(AF8:AJ8)>=2,ROUND(_xlfn.STDEV.S(AF8:AJ8),3),"") -> 0 | AN8: =ROUND((IF(AF8="",0,AF8)*Assumptions!$F$15)+(IF(AG8="",0,AG8)*Assumptions!$F$16)+(IF(AH8="",0,AH8)*Assumptions!$F$17)+(IF(AI8="",0,AI8)*Assumptions!$F$18)+(IF(AJ8="",0,AJ8)*Assumptions!$F$19),3) -> 4 | AO8: =IF(AC8<=20,"",IF(AC8<=Assumptions!$F$6,"20-30",IF(AC8<=Assumptions!$F$7,"30-40",IF(AC8<=Assumptions!$F$8,"40-50",IF(AC8<=Assumptions!$F$9,"50-60",IF(AC8<=Assumptions!$F$10,"60+","")))))) -> 40-50 | AP8: =IFERROR(VLOOKUP(O8,Assumptions!$B$14:$C$26,2,FALSE()),"Other") -> Leadership | AQ8: =IF(T8="",0,1) -> 1 | AR8: =IF(U8="",0,1) -> 1 | AS8: =IF(AK8="","",IF(MAX($AK$2:$AK$921)=MIN($AK$2:$AK$921),50,ROUND((AK8-MIN($AK$2:$AK$921))/(MAX($AK$2:$AK$921)-MIN($AK$2:$AK$921))*100,2))) -> 100 | AT8: =IF(MAX($BC$2:$BC$921)=MIN($BC$2:$BC$921),50,ROUND((BC8-MIN($BC$2:$BC$921))/(MAX($BC$2:$BC$921)-MIN($BC$2:$BC$921))*100,2)) -> 50 | AU8: =IF(MAX($BE$2:$BE$921)=MIN($BE$2:$BE$921),50,ROUND((BE8-MIN($BE$2:$BE$921))/(MAX($BE$2:$BE$921)-MIN($BE$2:$BE$921))*100,2)) -> 100 | AV8: =IF(MAX($AD$2:$AD$921)=MIN($AD$2:$AD$921),50,ROUND((AD8-MIN($AD$2:$AD$921))/(MAX($AD$2:$AD$921)-MIN($AD$2:$AD$921))*100,2)) -> 64.12 | AW8: =IF(MAX($AN$2:$AN$921)=MIN($AN$2:$AN$921),50,ROUND((AN8-MIN($AN$2:$AN$921))/(MAX($AN$2:$AN$921)-MIN($AN$2:$AN$921))*100,2)) -> 100 | AX8: =AQ8*100 -> 100 | AY8: =AR8*100 -> 100 | AZ8: =IFERROR(ROUND(AS8*Assumptions!$I$6+AW8*Assumptions!$I$7+AT8*Assumptions!$I$8+AU8*Assumptions!$I$9+AV8*Assumptions!$I$10+AX8*Assumptions!$I$11+AY8*Assumptions!$I$12,2),"") -> 88.91 | BA8: =IF(AZ8="","",IF(AZ8<=Assumptions!$I$18,"Below Expectation",IF(AZ8<=Assumptions!$I$19,"Developing",IF(AZ8<=Assumptions!$I$20,"Meets Expectation",IF(AZ8<=Assumptions!$I$21,"Exceeds","Star Performer"))))) -> Star Performer | BB8: =IF(AZ8="",0,IF(AZ8>=Assumptions!$I$26,1,0)) -> 1 | BC8: =IF(AL8="",2,AL8+2) -> 2 | BD8: =IF(AM8="",ROUND(AVERAGE($AM$2:$AM$921),3),AM8) -> 0 | BE8: =1-BD8 -> 1
A9: 18 | B9: 573601 | C9: Enterprise Application Management | D9: Mr. Ajit S Parab | E9: E&M IT Material & Service Commitment | F9: Group Commercial Platform CIO | G9: 24281719 | H9: Chief Engineering & Tech | I9: Bharat Bhushan | J9: Mr. Hemant Jain | K9: Marrd. | L9: 33484 | M9: 56.1 | N9: 25672 | O9: Vice President | P9: Vice - President | Q9: 34.9 | R9: . | S9: 34.9 | T9: 41000 | U9: 44440 | V9: A+ | W9: A* | X9: A* | Y9: A* | Z9: A* | AA9: MMM-Marketing-2001(PT),Diploma - Management-Finance-1996(CO),BE-Mechanical-1991(FT) | AB9: =IFERROR(VALUE(R9),0) -> 0 | AC9: =IFERROR(VALUE(M9),"") -> 56.1 | AD9: =IFERROR(VALUE(Q9),"") -> 34.9 | AE9: =IFERROR(VALUE(S9),"") -> 34.9 | AF9: =IF(V9="","",VLOOKUP(V9,Assumptions!$B$6:$C$9,2,FALSE())) -> 3 | AG9: =IF(W9="","",VLOOKUP(W9,Assumptions!$B$6:$C$9,2,FALSE())) -> 4 | AH9: =IF(X9="","",VLOOKUP(X9,Assumptions!$B$6:$C$9,2,FALSE())) -> 4 | AI9: =IF(Y9="","",VLOOKUP(Y9,Assumptions!$B$6:$C$9,2,FALSE())) -> 4 | AJ9: =IF(Z9="","",VLOOKUP(Z9,Assumptions!$B$6:$C$9,2,FALSE())) -> 4 | AK9: =IFERROR(ROUND(AVERAGE(AF9:AJ9),3),"") -> 3.8 | AL9: =IF(OR(AF9="",AJ9=""),"",AJ9-AF9) -> 1 | AM9: =IF(COUNT(AF9:AJ9)>=2,ROUND(_xlfn.STDEV.S(AF9:AJ9),3),"") -> 0.447 | AN9: =ROUND((IF(AF9="",0,AF9)*Assumptions!$F$15)+(IF(AG9="",0,AG9)*Assumptions!$F$16)+(IF(AH9="",0,AH9)*Assumptions!$F$17)+(IF(AI9="",0,AI9)*Assumptions!$F$18)+(IF(AJ9="",0,AJ9)*Assumptions!$F$19),3) -> 3.9 | AO9: =IF(AC9<=20,"",IF(AC9<=Assumptions!$F$6,"20-30",IF(AC9<=Assumptions!$F$7,"30-40",IF(AC9<=Assumptions!$F$8,"40-50",IF(AC9<=Assumptions!$F$9,"50-60",IF(AC9<=Assumptions!$F$10,"60+","")))))) -> 50-60 | AP9: =IFERROR(VLOOKUP(O9,Assumptions!$B$14:$C$26,2,FALSE()),"Other") -> Leadership | AQ9: =IF(T9="",0,1) -> 1 | AR9: =IF(U9="",0,1) -> 1 | AS9: =IF(AK9="","",IF(MAX($AK$2:$AK$921)=MIN($AK$2:$AK$921),50,ROUND((AK9-MIN($AK$2:$AK$921))/(MAX($AK$2:$AK$921)-MIN($AK$2:$AK$921))*100,2))) -> 91.43 | AT9: =IF(MAX($BC$2:$BC$921)=MIN($BC$2:$BC$921),50,ROUND((BC9-MIN($BC$2:$BC$921))/(MAX($BC$2:$BC$921)-MIN($BC$2:$BC$921))*100,2)) -> 75 | AU9: =IF(MAX($BE$2:$BE$921)=MIN($BE$2:$BE$921),50,ROUND((BE9-MIN($BE$2:$BE$921))/(MAX($BE$2:$BE$921)-MIN($BE$2:$BE$921))*100,2)) -> 74.19 | AV9: =IF(MAX($AD$2:$AD$921)=MIN($AD$2:$AD$921),50,ROUND((AD9-MIN($AD$2:$AD$921))/(MAX($AD$2:$AD$921)-MIN($AD$2:$AD$921))*100,2)) -> 94.56 | AW9: =IF(MAX($AN$2:$AN$921)=MIN($AN$2:$AN$921),50,ROUND((AN9-MIN($AN$2:$AN$921))/(MAX($AN$2:$AN$921)-MIN($AN$2:$AN$921))*100,2)) -> 97.5 | AX9: =AQ9*100 -> 100 | AY9: =AR9*100 -> 100 | AZ9: =IFERROR(ROUND(AS9*Assumptions!$I$6+AW9*Assumptions!$I$7+AT9*Assumptions!$I$8+AU9*Assumptions!$I$9+AV9*Assumptions!$I$10+AX9*Assumptions!$I$11+AY9*Assumptions!$I$12,2),"") -> 88.76 | BA9: =IF(AZ9="","",IF(AZ9<=Assumptions!$I$18,"Below Expectation",IF(AZ9<=Assumptions!$I$19,"Developing",IF(AZ9<=Assumptions!$I$20,"Meets Expectation",IF(AZ9<=Assumptions!$I$21,"Exceeds","Star Performer"))))) -> Star Performer | BB9: =IF(AZ9="",0,IF(AZ9>=Assumptions!$I$26,1,0)) -> 1 | BC9: =IF(AL9="",2,AL9+2) -> 3 | BD9: =IF(AM9="",ROUND(AVERAGE($AM$2:$AM$921),3),AM9) -> 0.447 | BE9: =1-BD9 -> 0.553
A10: 39 | B10: 10001835 | C10: Enterprise Application Management | D10: Mr. Hardik Dave | E10: E&M IT HR Platforms | F10: Chief Engineering & Tech | G10: 24281719 | H10: Chief Engineering & Tech | I10: Bharat Bhushan | J10: Mr. Hemant Jain | K10: Marrd. | L10: 37970 | M10: 51.1 | N10: 27503 | O10: Vice President | P10: Vice - President | Q10: 22.5 | R10: 5.6 | S10: 27.11 | T10: 43598 | U10: 44440 | V10: A* | W10: A* | X10: A* | Y10: A* | Z10: A* | AA10: PhD-Computer Programming-2006,MCA-Computer Applications-1998,BSc-Chemistry-1995 | AB10: =IFERROR(VALUE(R10),0) -> 5.6 | AC10: =IFERROR(VALUE(M10),"") -> 51.1 | AD10: =IFERROR(VALUE(Q10),"") -> 22.5 | AE10: =IFERROR(VALUE(S10),"") -> 27.11 | AF10: =IF(V10="","",VLOOKUP(V10,Assumptions!$B$6:$C$9,2,FALSE())) -> 4 | AG10: =IF(W10="","",VLOOKUP(W10,Assumptions!$B$6:$C$9,2,FALSE())) -> 4 | AH10: =IF(X10="","",VLOOKUP(X10,Assumptions!$B$6:$C$9,2,FALSE())) -> 4 | AI10: =IF(Y10="","",VLOOKUP(Y10,Assumptions!$B$6:$C$9,2,FALSE())) -> 4 | AJ10: =IF(Z10="","",VLOOKUP(Z10,Assumptions!$B$6:$C$9,2,FALSE())) -> 4 | AK10: =IFERROR(ROUND(AVERAGE(AF10:AJ10),3),"") -> 4 | AL10: =IF(OR(AF10="",AJ10=""),"",AJ10-AF10) -> 0 | AM10: =IF(COUNT(AF10:AJ10)>=2,ROUND(_xlfn.STDEV.S(AF10:AJ10),3),"") -> 0 | AN10: =ROUND((IF(AF10="",0,AF10)*Assumptions!$F$15)+(IF(AG10="",0,AG10)*Assumptions!$F$16)+(IF(AH10="",0,AH10)*Assumptions!$F$17)+(IF(AI10="",0,AI10)*Assumptions!$F$18)+(IF(AJ10="",0,AJ10)*Assumptions!$F$19),3) -> 4 | AO10: =IF(AC10<=20,"",IF(AC10<=Assumptions!$F$6,"20-30",IF(AC10<=Assumptions!$F$7,"30-40",IF(AC10<=Assumptions!$F$8,"40-50",IF(AC10<=Assumptions!$F$9,"50-60",IF(AC10<=Assumptions!$F$10,"60+","")))))) -> 50-60 | AP10: =IFERROR(VLOOKUP(O10,Assumptions!$B$14:$C$26,2,FALSE()),"Other") -> Leadership | AQ10: =IF(T10="",0,1) -> 1 | AR10: =IF(U10="",0,1) -> 1 | AS10: =IF(AK10="","",IF(MAX($AK$2:$AK$921)=MIN($AK$2:$AK$921),50,ROUND((AK10-MIN($AK$2:$AK$921))/(MAX($AK$2:$AK$921)-MIN($AK$2:$AK$921))*100,2))) -> 100 | AT10: =IF(MAX($BC$2:$BC$921)=MIN($BC$2:$BC$921),50,ROUND((BC10-MIN($BC$2:$BC$921))/(MAX($BC$2:$BC$921)-MIN($BC$2:$BC$921))*100,2)) -> 50 | AU10: =IF(MAX($BE$2:$BE$921)=MIN($BE$2:$BE$921),50,ROUND((BE10-MIN($BE$2:$BE$921))/(MAX($BE$2:$BE$921)-MIN($BE$2:$BE$921))*100,2)) -> 100 | AV10: =IF(MAX($AD$2:$AD$921)=MIN($AD$2:$AD$921),50,ROUND((AD10-MIN($AD$2:$AD$921))/(MAX($AD$2:$AD$921)-MIN($AD$2:$AD$921))*100,2)) -> 60.86 | AW10: =IF(MAX($AN$2:$AN$921)=MIN($AN$2:$AN$921),50,ROUND((AN10-MIN($AN$2:$AN$921))/(MAX($AN$2:$AN$921)-MIN($AN$2:$AN$921))*100,2)) -> 100 | AX10: =AQ10*100 -> 100 | AY10: =AR10*100 -> 100 | AZ10: =IFERROR(ROUND(AS10*Assumptions!$I$6+AW10*Assumptions!$I$7+AT10*Assumptions!$I$8+AU10*Assumptions!$I$9+AV10*Assumptions!$I$10+AX10*Assumptions!$I$11+AY10*Assumptions!$I$12,2),"") -> 88.59 | BA10: =IF(AZ10="","",IF(AZ10<=Assumptions!$I$18,"Below Expectation",IF(AZ10<=Assumptions!$I$19,"Developing",IF(AZ10<=Assumptions!$I$20,"Meets Expectation",IF(AZ10<=Assumptions!$I$21,"Exceeds","Star Performer"))))) -> Star Performer | BB10: =IF(AZ10="",0,IF(AZ10>=Assumptions!$I$26,1,0)) -> 1 | BC10: =IF(AL10="",2,AL10+2) -> 2 | BD10: =IF(AM10="",ROUND(AVERAGE($AM$2:$AM$921),3),AM10) -> 0 | BE10: =1-BD10 -> 1
A11: 350 | B11: 37100262 | C11: IRM & Cyber Security | D11: Mr. Rajesh Shethia | E11: IRM Vulnerability Management | F11: Head Information Security | G11: 24281827 | H11: Head Information Security | I11: Bharat Bhushan | J11: Ms. Sudeshna Das | K11: Marrd. | L11: 38268 | M11: 47.5 | N11: 28836 | O11: Asst. Vice President | P11: Asst. Vice - President | Q11: 21.8 | R11: 2.11 | S11: 24.7 | T11: 42751 | U11: 44440 | V11: A* | W11: A* | X11: A* | Y11: A* | Z11: A* | AA11: BE-Chemical-2001 | AB11: =IFERROR(VALUE(R11),0) -> 2.11 | AC11: =IFERROR(VALUE(M11),"") -> 47.5 | AD11: =IFERROR(VALUE(Q11),"") -> 21.8 | AE11: =IFERROR(VALUE(S11),"") -> 24.7 | AF11: =IF(V11="","",VLOOKUP(V11,Assumptions!$B$6:$C$9,2,FALSE())) -> 4 | AG11: =IF(W11="","",VLOOKUP(W11,Assumptions!$B$6:$C$9,2,FALSE())) -> 4 | AH11: =IF(X11="","",VLOOKUP(X11,Assumptions!$B$6:$C$9,2,FALSE())) -> 4 | AI11: =IF(Y11="","",VLOOKUP(Y11,Assumptions!$B$6:$C$9,2,FALSE())) -> 4 | AJ11: =IF(Z11="","",VLOOKUP(Z11,Assumptions!$B$6:$C$9,2,FALSE())) -> 4 | AK11: =IFERROR(ROUND(AVERAGE(AF11:AJ11),3),"") -> 4 | AL11: =IF(OR(AF11="",AJ11=""),"",AJ11-AF11) -> 0 | AM11: =IF(COUNT(AF11:AJ11)>=2,ROUND(_xlfn.STDEV.S(AF11:AJ11),3),"") -> 0 | AN11: =ROUND((IF(AF11="",0,AF11)*Assumptions!$F$15)+(IF(AG11="",0,AG11)*Assumptions!$F$16)+(IF(AH11="",0,AH11)*Assumptions!$F$17)+(IF(AI11="",0,AI11)*Assumptions!$F$18)+(IF(AJ11="",0,AJ11)*Assumptions!$F$19),3) -> 4 | AO11: =IF(AC11<=20,"",IF(AC11<=Assumptions!$F$6,"20-30",IF(AC11<=Assumptions!$F$7,"30-40",IF(AC11<=Assumptions!$F$8,"40-50",IF(AC11<=Assumptions!$F$9,"50-60",IF(AC11<=Assumptions!$F$10,"60+","")))))) -> 40-50 | AP11: =IFERROR(VLOOKUP(O11,Assumptions!$B$14:$C$26,2,FALSE()),"Other") -> Leadership | AQ11: =IF(T11="",0,1) -> 1 | AR11: =IF(U11="",0,1) -> 1 | AS11: =IF(AK11="","",IF(MAX($AK$2:$AK$921)=MIN($AK$2:$AK$921),50,ROUND((AK11-MIN($AK$2:$AK$921))/(MAX($AK$2:$AK$921)-MIN($AK$2:$AK$921))*100,2))) -> 100 | AT11: =IF(MAX($BC$2:$BC$921)=MIN($BC$2:$BC$921),50,ROUND((BC11-MIN($BC$2:$BC$921))/(MAX($BC$2:$BC$921)-MIN($BC$2:$BC$921))*100,2)) -> 50 | AU11: =IF(MAX($BE$2:$BE$921)=MIN($BE$2:$BE$921),50,ROUND((BE11-MIN($BE$2:$BE$921))/(MAX($BE$2:$BE$921)-MIN($BE$2:$BE$921))*100,2)) -> 100 | AV11: =IF(MAX($AD$2:$AD$921)=MIN($AD$2:$AD$921),50,ROUND((AD11-MIN($AD$2:$AD$921))/(MAX($AD$2:$AD$921)-MIN($AD$2:$AD$921))*100,2)) -> 58.96 | AW11: =IF(MAX($AN$2:$AN$921)=MIN($AN$2:$AN$921),50,ROUND((AN11-MIN($AN$2:$AN$921))/(MAX($AN$2:$AN$921)-MIN($AN$2:$AN$921))*100,2)) -> 100 | AX11: =AQ11*100 -> 100 | AY11: =AR11*100 -> 100 | AZ11: =IFERROR(ROUND(AS11*Assumptions!$I$6+AW11*Assumptions!$I$7+AT11*Assumptions!$I$8+AU11*Assumptions!$I$9+AV11*Assumptions!$I$10+AX11*Assumptions!$I$11+AY11*Assumptions!$I$12,2),"") -> 88.4 | BA11: =IF(AZ11="","",IF(AZ11<=Assumptions!$I$18,"Below Expectation",IF(AZ11<=Assumptions!$I$19,"Developing",IF(AZ11<=Assumptions!$I$20,"Meets Expectation",IF(AZ11<=Assumptions!$I$21,"Exceeds","Star Performer"))))) -> Star Performer | BB11: =IF(AZ11="",0,IF(AZ11>=Assumptions!$I$26,1,0)) -> 1 | BC11: =IF(AL11="",2,AL11+2) -> 2 | BD11: =IF(AM11="",ROUND(AVERAGE($AM$2:$AM$921),3),AM11) -> 0 | BE11: =1-BD11 -> 1
A12: 42 | B12: 10005916 | C12: JioCX | D12: Mr. Prashant Ayare | E12: JioCX Engineering | F12: Team Lead Software Development | G12: 24281768 | H12: Team Lead Software Development | I12: Bharat Bhushan | J12: Ms. Arya Khamparia | K12: Marrd. | L12: 38290 | M12: 46.1 | N12: 29339 | O12: General Manager | P12: General Manager | Q12: 21.7 | R12: 3.5 | S12: 25.0 | T12: 43598 | U12: 44440 | V12: A* | W12: A* | X12: A* | Y12: A* | Z12: A* | AA12: Master in Information Management (MIM)-Project Management-2009,BCom-Commerce-2000 | AB12: =IFERROR(VALUE(R12),0) -> 3.5 | AC12: =IFERROR(VALUE(M12),"") -> 46.1 | AD12: =IFERROR(VALUE(Q12),"") -> 21.7 | AE12: =IFERROR(VALUE(S12),"") -> 25 | AF12: =IF(V12="","",VLOOKUP(V12,Assumptions!$B$6:$C$9,2,FALSE())) -> 4 | AG12: =IF(W12="","",VLOOKUP(W12,Assumptions!$B$6:$C$9,2,FALSE())) -> 4 | AH12: =IF(X12="","",VLOOKUP(X12,Assumptions!$B$6:$C$9,2,FALSE())) -> 4 | AI12: =IF(Y12="","",VLOOKUP(Y12,Assumptions!$B$6:$C$9,2,FALSE())) -> 4 | AJ12: =IF(Z12="","",VLOOKUP(Z12,Assumptions!$B$6:$C$9,2,FALSE())) -> 4 | AK12: =IFERROR(ROUND(AVERAGE(AF12:AJ12),3),"") -> 4 | AL12: =IF(OR(AF12="",AJ12=""),"",AJ12-AF12) -> 0 | AM12: =IF(COUNT(AF12:AJ12)>=2,ROUND(_xlfn.STDEV.S(AF12:AJ12),3),"") -> 0 | AN12: =ROUND((IF(AF12="",0,AF12)*Assumptions!$F$15)+(IF(AG12="",0,AG12)*Assumptions!$F$16)+(IF(AH12="",0,AH12)*Assumptions!$F$17)+(IF(AI12="",0,AI12)*Assumptions!$F$18)+(IF(AJ12="",0,AJ12)*Assumptions!$F$19),3) -> 4 | AO12: =IF(AC12<=20,"",IF(AC12<=Assumptions!$F$6,"20-30",IF(AC12<=Assumptions!$F$7,"30-40",IF(AC12<=Assumptions!$F$8,"40-50",IF(AC12<=Assumptions!$F$9,"50-60",IF(AC12<=Assumptions!$F$10,"60+","")))))) -> 40-50 | AP12: =IFERROR(VLOOKUP(O12,Assumptions!$B$14:$C$26,2,FALSE()),"Other") -> Manager | AQ12: =IF(T12="",0,1) -> 1 | AR12: =IF(U12="",0,1) -> 1 | AS12: =IF(AK12="","",IF(MAX($AK$2:$AK$921)=MIN($AK$2:$AK$921),50,ROUND((AK12-MIN($AK$2:$AK$921))/(MAX($AK$2:$AK$921)-MIN($AK$2:$AK$921))*100,2))) -> 100 | AT12: =IF(MAX($BC$2:$BC$921)=MIN($BC$2:$BC$921),50,ROUND((BC12-MIN($BC$2:$BC$921))/(MAX($BC$2:$BC$921)-MIN($BC$2:$BC$921))*100,2)) -> 50 | AU12: =IF(MAX($BE$2:$BE$921)=MIN($BE$2:$BE$921),50,ROUND((BE12-MIN($BE$2:$BE$921))/(MAX($BE$2:$BE$921)-MIN($BE$2:$BE$921))*100,2)) -> 100 | AV12: =IF(MAX($AD$2:$AD$921)=MIN($AD$2:$AD$921),50,ROUND((AD12-MIN($AD$2:$AD$921))/(MAX($AD$2:$AD$921)-MIN($AD$2:$AD$921))*100,2)) -> 58.68 | AW12: =IF(MAX($AN$2:$AN$921)=MIN($AN$2:$AN$921),50,ROUND((AN12-MIN($AN$2:$AN$921))/(MAX($AN$2:$AN$921)-MIN($AN$2:$AN$921))*100,2)) -> 100 | AX12: =AQ12*100 -> 100 | AY12: =AR12*100 -> 100 | AZ12: =IFERROR(ROUND(AS12*Assumptions!$I$6+AW12*Assumptions!$I$7+AT12*Assumptions!$I$8+AU12*Assumptions!$I$9+AV12*Assumptions!$I$10+AX12*Assumptions!$I$11+AY12*Assumptions!$I$12,2),"") -> 88.37 | BA12: =IF(AZ12="","",IF(AZ12<=Assumptions!$I$18,"Below Expectation",IF(AZ12<=Assumptions!$I$19,"Developing",IF(AZ12<=Assumptions!$I$20,"Meets Expectation",IF(AZ12<=Assumptions!$I$21,"Exceeds","Star Performer"))))) -> Star Performer | BB12: =IF(AZ12="",0,IF(AZ12>=Assumptions!$I$26,1,0)) -> 1 | BC12: =IF(AL12="",2,AL12+2) -> 2 | BD12: =IF(AM12="",ROUND(AVERAGE($AM$2:$AM$921),3),AM12) -> 0 | BE12: =1-BD12 -> 1
A13: 359 | B13: 37101494 | C13: Enterprise Application Management | D13: Mr. Bhavin K Acharya | E13: E&M IT SAP Tech Ops | F13: Head Tech Operations | G13: 24281778 | H13: Head Tech Operations | I13: Bharat Bhushan | J13: Mr. Hemant Jain | K13: Marrd. | L13: 39182 | M13: 55.0 | N13: 26067 | O13: Asst. Vice President | P13: Asst. Vice - President | Q13: 19.1 | R13: 11.7 | S13: 30.8 | T13: 42917 | U13: 44440 | V13: A* | W13: A* | X13: A* | Y13: A* | Z13: A* | AA13: MCA-Computer Applications-2004,MSc-Physics-1994,BSc-Physics-1992 | AB13: =IFERROR(VALUE(R13),0) -> 11.7 | AC13: =IFERROR(VALUE(M13),"") -> 55 | AD13: =IFERROR(VALUE(Q13),"") -> 19.1 | AE13: =IFERROR(VALUE(S13),"") -> 30.8 | AF13: =IF(V13="","",VLOOKUP(V13,Assumptions!$B$6:$C$9,2,FALSE())) -> 4 | AG13: =IF(W13="","",VLOOKUP(W13,Assumptions!$B$6:$C$9,2,FALSE())) -> 4 | AH13: =IF(X13="","",VLOOKUP(X13,Assumptions!$B$6:$C$9,2,FALSE())) -> 4 | AI13: =IF(Y13="","",VLOOKUP(Y13,Assumptions!$B$6:$C$9,2,FALSE())) -> 4 | AJ13: =IF(Z13="","",VLOOKUP(Z13,Assumptions!$B$6:$C$9,2,FALSE())) -> 4 | AK13: =IFERROR(ROUND(AVERAGE(AF13:AJ13),3),"") -> 4 | AL13: =IF(OR(AF13="",AJ13=""),"",AJ13-AF13) -> 0 | AM13: =IF(COUNT(AF13:AJ13)>=2,ROUND(_xlfn.STDEV.S(AF13:AJ13),3),"") -> 0 | AN13: =ROUND((IF(AF13="",0,AF13)*Assumptions!$F$15)+(IF(AG13="",0,AG13)*Assumptions!$F$16)+(IF(AH13="",0,AH13)*Assumptions!$F$17)+(IF(AI13="",0,AI13)*Assumptions!$F$18)+(IF(AJ13="",0,AJ13)*Assumptions!$F$19),3) -> 4 | AO13: =IF(AC13<=20,"",IF(AC13<=Assumptions!$F$6,"20-30",IF(AC13<=Assumptions!$F$7,"30-40",IF(AC13<=Assumptions!$F$8,"40-50",IF(AC13<=Assumptions!$F$9,"50-60",IF(AC13<=Assumptions!$F$10,"60+","")))))) -> 50-60 | AP13: =IFERROR(VLOOKUP(O13,Assumptions!$B$14:$C$26,2,FALSE()),"Other") -> Leadership | AQ13: =IF(T13="",0,1) -> 1 | AR13: =IF(U13="",0,1) -> 1 | AS13: =IF(AK13="","",IF(MAX($AK$2:$AK$921)=MIN($AK$2:$AK$921),50,ROUND((AK13-MIN($AK$2:$AK$921))/(MAX($AK$2:$AK$921)-MIN($AK$2:$AK$921))*100,2))) -> 100 | AT13: =IF(MAX($BC$2:$BC$921)=MIN($BC$2:$BC$921),50,ROUND((BC13-MIN($BC$2:$BC$921))/(MAX($BC$2:$BC$921)-MIN($BC$2:$BC$921))*100,2)) -> 50 | AU13: =IF(MAX($BE$2:$BE$921)=MIN($BE$2:$BE$921),50,ROUND((BE13-MIN($BE$2:$BE$921))/(MAX($BE$2:$BE$921)-MIN($BE$2:$BE$921))*100,2)) -> 100 | AV13: =IF(MAX($AD$2:$AD$921)=MIN($AD$2:$AD$921),50,ROUND((AD13-MIN($AD$2:$AD$921))/(MAX($AD$2:$AD$921)-MIN($AD$2:$AD$921))*100,2)) -> 51.62 | AW13: =IF(MAX($AN$2:$AN$921)=MIN($AN$2:$AN$921),50,ROUND((AN13-MIN($AN$2:$AN$921))/(MAX($AN$2:$AN$921)-MIN($AN$2:$AN$921))*100,2)) -> 100 | AX13: =AQ13*100 -> 100 | AY13: =AR13*100 -> 100 | AZ13: =IFERROR(ROUND(AS13*Assumptions!$I$6+AW13*Assumptions!$I$7+AT13*Assumptions!$I$8+AU13*Assumptions!$I$9+AV13*Assumptions!$I$10+AX13*Assumptions!$I$11+AY13*Assumptions!$I$12,2),"") -> 87.66 | BA13: =IF(AZ13="","",IF(AZ13<=Assumptions!$I$18,"Below Expectation",IF(AZ13<=Assumptions!$I$19,"Developing",IF(AZ13<=Assumptions!$I$20,"Meets Expectation",IF(AZ13<=Assumptions!$I$21,"Exceeds","Star Performer"))))) -> Star Performer | BB13: =IF(AZ13="",0,IF(AZ13>=Assumptions!$I$26,1,0)) -> 1 | BC13: =IF(AL13="",2,AL13+2) -> 2 | BD13: =IF(AM13="",ROUND(AVERAGE($AM$2:$AM$921),3),AM13) -> 0 | BE13: =1-BD13 -> 1
A14: 441 | B14: 55000019 | C14: JioCX | D14: Mr. Jitendra Bhatia | E14: JioCX Engineering | F14: Head Architecture JioCX | G14: 24281724 | H14: Head Architecture | I14: Bharat Bhushan | J14: Ms. Arya Khamparia | K14: Marrd. | L14: 39580 | M14: 47.9 | N14: 28740 | O14: Asst. Vice President | P14: Asst. Vice - President | Q14: 18 | R14: 8.10 | S14: 26.10 | T14: 41730 | U14: 43556 | V14: A* | W14: A* | X14: A* | Y14: A* | Z14: A* | AA14: BE-Electronics & Comm. Engg-2001(FT) | AB14: =IFERROR(VALUE(R14),0) -> 8.1 | AC14: =IFERROR(VALUE(M14),"") -> 47.9 | AD14: =IFERROR(VALUE(Q14),"") -> 18 | AE14: =IFERROR(VALUE(S14),"") -> 26.1 | AF14: =IF(V14="","",VLOOKUP(V14,Assumptions!$B$6:$C$9,2,FALSE())) -> 4 | AG14: =IF(W14="","",VLOOKUP(W14,Assumptions!$B$6:$C$9,2,FALSE())) -> 4 | AH14: =IF(X14="","",VLOOKUP(X14,Assumptions!$B$6:$C$9,2,FALSE())) -> 4 | AI14: =IF(Y14="","",VLOOKUP(Y14,Assumptions!$B$6:$C$9,2,FALSE())) -> 4 | AJ14: =IF(Z14="","",VLOOKUP(Z14,Assumptions!$B$6:$C$9,2,FALSE())) -> 4 | AK14: =IFERROR(ROUND(AVERAGE(AF14:AJ14),3),"") -> 4 | AL14: =IF(OR(AF14="",AJ14=""),"",AJ14-AF14) -> 0 | AM14: =IF(COUNT(AF14:AJ14)>=2,ROUND(_xlfn.STDEV.S(AF14:AJ14),3),"") -> 0 | AN14: =ROUND((IF(AF14="",0,AF14)*Assumptions!$F$15)+(IF(AG14="",0,AG14)*Assumptions!$F$16)+(IF(AH14="",0,AH14)*Assumptions!$F$17)+(IF(AI14="",0,AI14)*Assumptions!$F$18)+(IF(AJ14="",0,AJ14)*Assumptions!$F$19),3) -> 4 | AO14: =IF(AC14<=20,"",IF(AC14<=Assumptions!$F$6,"20-30",IF(AC14<=Assumptions!$F$7,"30-40",IF(AC14<=Assumptions!$F$8,"40-50",IF(AC14<=Assumptions!$F$9,"50-60",IF(AC14<=Assumptions!$F$10,"60+","")))))) -> 40-50 | AP14: =IFERROR(VLOOKUP(O14,Assumptions!$B$14:$C$26,2,FALSE()),"Other") -> Leadership | AQ14: =IF(T14="",0,1) -> 1 | AR14: =IF(U14="",0,1) -> 1 | AS14: =IF(AK14="","",IF(MAX($AK$2:$AK$921)=MIN($AK$2:$AK$921),50,ROUND((AK14-MIN($AK$2:$AK$921))/(MAX($AK$2:$AK$921)-MIN($AK$2:$AK$921))*100,2))) -> 100 | AT14: =IF(MAX($BC$2:$BC$921)=MIN($BC$2:$BC$921),50,ROUND((BC14-MIN($BC$2:$BC$921))/(MAX($BC$2:$BC$921)-MIN($BC$2:$BC$921))*100,2)) -> 50 | AU14: =IF(MAX($BE$2:$BE$921)=MIN($BE$2:$BE$921),50,ROUND((BE14-MIN($BE$2:$BE$921))/(MAX($BE$2:$BE$921)-MIN($BE$2:$BE$921))*100,2)) -> 100 | AV14: =IF(MAX($AD$2:$AD$921)=MIN($AD$2:$AD$921),50,ROUND((AD14-MIN($AD$2:$AD$921))/(MAX($AD$2:$AD$921)-MIN($AD$2:$AD$921))*100,2)) -> 48.63 | AW14: =IF(MAX($AN$2:$AN$921)=MIN($AN$2:$AN$921),50,ROUND((AN14-MIN($AN$2:$AN$921))/(MAX($AN$2:$AN$921)-MIN($AN$2:$AN$921))*100,2)) -> 100 | AX14: =AQ14*100 -> 100 | AY14: =AR14*100 -> 100 | AZ14: =IFERROR(ROUND(AS14*Assumptions!$I$6+AW14*Assumptions!$I$7+AT14*Assumptions!$I$8+AU14*Assumptions!$I$9+AV14*Assumptions!$I$10+AX14*Assumptions!$I$11+AY14*Assumptions!$I$12,2),"") -> 87.36 | BA14: =IF(AZ14="","",IF(AZ14<=Assumptions!$I$18,"Below Expectation",IF(AZ14<=Assumptions!$I$19,"Developing",IF(AZ14<=Assumptions!$I$20,"Meets Expectation",IF(AZ14<=Assumptions!$I$21,"Exceeds","Star Performer"))))) -> Star Performer | BB14: =IF(AZ14="",0,IF(AZ14>=Assumptions!$I$26,1,0)) -> 1 | BC14: =IF(AL14="",2,AL14+2) -> 2 | BD14: =IF(AM14="",ROUND(AVERAGE($AM$2:$AM$921),3),AM14) -> 0 | BE14: =1-BD14 -> 1
... A24: 2 | B24: 7214 | C24: IT Infrastructure | D24: Mr. Suresh Kumar | E24: Infrastructure Projects | F24: Chief - IT Infrastructure | G24: 24281819 | H24: Chief IT Infrastructure | I24: Bharat Bhushan | J24: Ms. Sudeshna Das | K24: Marrd. | L24: 34348 | M24: 56.9 | N24: 25433 | O24: Vice President | P24: Vice - President | Q24: 32.4 | R24: . | S24: 32.4 | T24: 40634 | U24: 44470 | V24: A+ | W24: A+ | X24: A* | Y24: A* | Z24: A* | AA24: Certificate Course-Computer Engg-1996,PGD in Computer Science-Computer Applications-1993,BCom-Commerce-1991 | AB24: =IFERROR(VALUE(R24),0) -> 0 | AC24: =IFERROR(VALUE(M24),"") -> 56.9 | AD24: =IFERROR(VALUE(Q24),"") -> 32.4 | AE24: =IFERROR(VALUE(S24),"") -> 32.4 | AF24: =IF(V24="","",VLOOKUP(V24,Assumptions!$B$6:$C$9,2,FALSE())) -> 3 | AG24: =IF(W24="","",VLOOKUP(W24,Assumptions!$B$6:$C$9,2,FALSE())) -> 3 | AH24: =IF(X24="","",VLOOKUP(X24,Assumptions!$B$6:$C$9,2,FALSE())) -> 4 | AI24: =IF(Y24="","",VLOOKUP(Y24,Assumptions!$B$6:$C$9,2,FALSE())) -> 4 | AJ24: =IF(Z24="","",VLOOKUP(Z24,Assumptions!$B$6:$C$9,2,FALSE())) -> 4 | AK24: =IFERROR(ROUND(AVERAGE(AF24:AJ24),3),"") -> 3.6 | AL24: =IF(OR(AF24="",AJ24=""),"",AJ24-AF24) -> 1 | AM24: =IF(COUNT(AF24:AJ24)>=2,ROUND(_xlfn.STDEV.S(AF24:AJ24),3),"") -> 0.548 | AN24: =ROUND((IF(AF24="",0,AF24)*Assumptions!$F$15)+(IF(AG24="",0,AG24)*Assumptions!$F$16)+(IF(AH24="",0,AH24)*Assumptions!$F$17)+(IF(AI24="",0,AI24)*Assumptions!$F$18)+(IF(AJ24="",0,AJ24)*Assumptions!$F$19),3) -> 3.75 | AO24: =IF(AC24<=20,"",IF(AC24<=Assumptions!$F$6,"20-30",IF(AC24<=Assumptions!$F$7,"30-40",IF(AC24<=Assumptions!$F$8,"40-50",IF(AC24<=Assumptions!$F$9,"50-60",IF(AC24<=Assumptions!$F$10,"60+","")))))) -> 50-60 | AP24: =IFERROR(VLOOKUP(O24,Assumptions!$B$14:$C$26,2,FALSE()),"Other") -> Leadership | AQ24: =IF(T24="",0,1) -> 1 | AR24: =IF(U24="",0,1) -> 1 | AS24: =IF(AK24="","",IF(MAX($AK$2:$AK$921)=MIN($AK$2:$AK$921),50,ROUND((AK24-MIN($AK$2:$AK$921))/(MAX($AK$2:$AK$921)-MIN($AK$2:$AK$921))*100,2))) -> 82.85 | AT24: =IF(MAX($BC$2:$BC$921)=MIN($BC$2:$BC$921),50,ROUND((BC24-MIN($BC$2:$BC$921))/(MAX($BC$2:$BC$921)-MIN($BC$2:$BC$921))*100,2)) -> 75 | AU24: =IF(MAX($BE$2:$BE$921)=MIN($BE$2:$BE$921),50,ROUND((BE24-MIN($BE$2:$BE$921))/(MAX($BE$2:$BE$921)-MIN($BE$2:$BE$921))*100,2)) -> 68.36 | AV24: =IF(MAX($AD$2:$AD$921)=MIN($AD$2:$AD$921),50,ROUND((AD24-MIN($AD$2:$AD$921))/(MAX($AD$2:$AD$921)-MIN($AD$2:$AD$921))*100,2)) -> 87.77 | AW24: =IF(MAX($AN$2:$AN$921)=MIN($AN$2:$AN$921),50,ROUND((AN24-MIN($AN$2:$AN$921))/(MAX($AN$2:$AN$921)-MIN($AN$2:$AN$921))*100,2)) -> 93.75 | AX24: =AQ24*100 -> 100 | AY24: =AR24*100 -> 100 | AZ24: =IFERROR(ROUND(AS24*Assumptions!$I$6+AW24*Assumptions!$I$7+AT24*Assumptions!$I$8+AU24*Assumptions!$I$9+AV24*Assumptions!$I$10+AX24*Assumptions!$I$11+AY24*Assumptions!$I$12,2),"") -> 83.89 | BA24: =IF(AZ24="","",IF(AZ24<=Assumptions!$I$18,"Below Expectation",IF(AZ24<=Assumptions!$I$19,"Developing",IF(AZ24<=Assumptions!$I$20,"Meets Expectation",IF(AZ24<=Assumptions!$I$21,"Exceeds","Star Performer"))))) -> Exceeds | BB24: =IF(AZ24="",0,IF(AZ24>=Assumptions!$I$26,1,0)) -> 1 | BC24: =IF(AL24="",2,AL24+2) -> 3 | BD24: =IF(AM24="",ROUND(AVERAGE($AM$2:$AM$921),3),AM24) -> 0.548 | BE24: =1-BD24 -> 0.452
A25: 419 | B25: 50009964 | D25: Mr. Ankit Vijay | E25: HR Platform Development & Business Supp | F25: Lead -Software Development | G25: 24281767 | H25: Lead Software Development | I25: Bharat Bhushan | J25: Mr. Hemant Jain | K25: Marrd. | L25: 40917 | M25: 38.5 | N25: 32135 | O25: DGM | P25: Dy. General Manager | Q25: 14.4 | R25: . | S25: 14.4 | T25: 42430 | U25: 44440 | V25: A+ | W25: A* | X25: A* | Y25: A* | Z25: A* | AA25: BTech-Information Technology-2010(FT) | AB25: =IFERROR(VALUE(R25),0) -> 0 | AC25: =IFERROR(VALUE(M25),"") -> 38.5 | AD25: =IFERROR(VALUE(Q25),"") -> 14.4 | AE25: =IFERROR(VALUE(S25),"") -> 14.4 | AF25: =IF(V25="","",VLOOKUP(V25,Assumptions!$B$6:$C$9,2,FALSE())) -> 3 | AG25: =IF(W25="","",VLOOKUP(W25,Assumptions!$B$6:$C$9,2,FALSE())) -> 4 | AH25: =IF(X25="","",VLOOKUP(X25,Assumptions!$B$6:$C$9,2,FALSE())) -> 4 | AI25: =IF(Y25="","",VLOOKUP(Y25,Assumptions!$B$6:$C$9,2,FALSE())) -> 4 | AJ25: =IF(Z25="","",VLOOKUP(Z25,Assumptions!$B$6:$C$9,2,FALSE())) -> 4 | AK25: =IFERROR(ROUND(AVERAGE(AF25:AJ25),3),"") -> 3.8 | AL25: =IF(OR(AF25="",AJ25=""),"",AJ25-AF25) -> 1 | AM25: =IF(COUNT(AF25:AJ25)>=2,ROUND(_xlfn.STDEV.S(AF25:AJ25),3),"") -> 0.447 | AN25: =ROUND((IF(AF25="",0,AF25)*Assumptions!$F$15)+(IF(AG25="",0,AG25)*Assumptions!$F$16)+(IF(AH25="",0,AH25)*Assumptions!$F$17)+(IF(AI25="",0,AI25)*Assumptions!$F$18)+(IF(AJ25="",0,AJ25)*Assumptions!$F$19),3) -> 3.9 | AO25: =IF(AC25<=20,"",IF(AC25<=Assumptions!$F$6,"20-30",IF(AC25<=Assumptions!$F$7,"30-40",IF(AC25<=Assumptions!$F$8,"40-50",IF(AC25<=Assumptions!$F$9,"50-60",IF(AC25<=Assumptions!$F$10,"60+","")))))) -> 30-40 | AP25: =IFERROR(VLOOKUP(O25,Assumptions!$B$14:$C$26,2,FALSE()),"Other") -> Manager | AQ25: =IF(T25="",0,1) -> 1 | AR25: =IF(U25="",0,1) -> 1 | AS25: =IF(AK25="","",IF(MAX($AK$2:$AK$921)=MIN($AK$2:$AK$921),50,ROUND((AK25-MIN($AK$2:$AK$921))/(MAX($AK$2:$AK$921)-MIN($AK$2:$AK$921))*100,2))) -> 91.43 | AT25: =IF(MAX($BC$2:$BC$921)=MIN($BC$2:$BC$921),50,ROUND((BC25-MIN($BC$2:$BC$921))/(MAX($BC$2:$BC$921)-MIN($BC$2:$BC$921))*100,2)) -> 75 | AU25: =IF(MAX($BE$2:$BE$921)=MIN($BE$2:$BE$921),50,ROUND((BE25-MIN($BE$2:$BE$921))/(MAX($BE$2:$BE$921)-MIN($BE$2:$BE$921))*100,2)) -> 74.19 | AV25: =IF(MAX($AD$2:$AD$921)=MIN($AD$2:$AD$921),50,ROUND((AD25-MIN($AD$2:$AD$921))/(MAX($AD$2:$AD$921)-MIN($AD$2:$AD$921))*100,2)) -> 38.84 | AW25: =IF(MAX($AN$2:$AN$921)=MIN($AN$2:$AN$921),50,ROUND((AN25-MIN($AN$2:$AN$921))/(MAX($AN$2:$AN$921)-MIN($AN$2:$AN$921))*100,2)) -> 97.5 | AX25: =AQ25*100 -> 100 | AY25: =AR25*100 -> 100 | AZ25: =IFERROR(ROUND(AS25*Assumptions!$I$6+AW25*Assumptions!$I$7+AT25*Assumptions!$I$8+AU25*Assumptions!$I$9+AV25*Assumptions!$I$10+AX25*Assumptions!$I$11+AY25*Assumptions!$I$12,2),"") -> 83.19 | BA25: =IF(AZ25="","",IF(AZ25<=Assumptions!$I$18,"Below Expectation",IF(AZ25<=Assumptions!$I$19,"Developing",IF(AZ25<=Assumptions!$I$20,"Meets Expectation",IF(AZ25<=Assumptions!$I$21,"Exceeds","Star Performer"))))) -> Exceeds | BB25: =IF(AZ25="",0,IF(AZ25>=Assumptions!$I$26,1,0)) -> 1 | BC25: =IF(AL25="",2,AL25+2) -> 3 | BD25: =IF(AM25="",ROUND(AVERAGE($AM$2:$AM$921),3),AM25) -> 0.447 | BE25: =1-BD25 -> 0.553
A26: 426 | B26: 50010485 | C26: Enterprise Application Management | D26: Mr. Vikas Chaturvedi | E26: E&M IT Oil & Gas | F26: Lead Architect | G26: 24281722 | H26: Lead Architect | I26: Bharat Bhushan | J26: Mr. Hemant Jain | K26: Marrd. | L26: 41037 | M26: 41.6 | N26: 31020 | O26: General Manager | P26: General Manager | Q26: 14.1 | R26: 2.10 | S26: 16.11 | T26: 42644 | U26: 46113 | V26: A+ | W26: A* | X26: A* | Y26: A* | Z26: A* | AA26: BE-Electronics Engg-2009(FT) | AB26: =IFERROR(VALUE(R26),0) -> 2.1 | AC26: =IFERROR(VALUE(M26),"") -> 41.6 | AD26: =IFERROR(VALUE(Q26),"") -> 14.1 | AE26: =IFERROR(VALUE(S26),"") -> 16.11 | AF26: =IF(V26="","",VLOOKUP(V26,Assumptions!$B$6:$C$9,2,FALSE())) -> 3 | AG26: =IF(W26="","",VLOOKUP(W26,Assumptions!$B$6:$C$9,2,FALSE())) -> 4 | AH26: =IF(X26="","",VLOOKUP(X26,Assumptions!$B$6:$C$9,2,FALSE())) -> 4 | AI26: =IF(Y26="","",VLOOKUP(Y26,Assumptions!$B$6:$C$9,2,FALSE())) -> 4 | AJ26: =IF(Z26="","",VLOOKUP(Z26,Assumptions!$B$6:$C$9,2,FALSE())) -> 4 | AK26: =IFERROR(ROUND(AVERAGE(AF26:AJ26),3),"") -> 3.8 | AL26: =IF(OR(AF26="",AJ26=""),"",AJ26-AF26) -> 1 | AM26: =IF(COUNT(AF26:AJ26)>=2,ROUND(_xlfn.STDEV.S(AF26:AJ26),3),"") -> 0.447 | AN26: =ROUND((IF(AF26="",0,AF26)*Assumptions!$F$15)+(IF(AG26="",0,AG26)*Assumptions!$F$16)+(IF(AH26="",0,AH26)*Assumptions!$F$17)+(IF(AI26="",0,AI26)*Assumptions!$F$18)+(IF(AJ26="",0,AJ26)*Assumptions!$F$19),3) -> 3.9 | AO26: =IF(AC26<=20,"",IF(AC26<=Assumptions!$F$6,"20-30",IF(AC26<=Assumptions!$F$7,"30-40",IF(AC26<=Assumptions!$F$8,"40-50",IF(AC26<=Assumptions!$F$9,"50-60",IF(AC26<=Assumptions!$F$10,"60+","")))))) -> 40-50 | AP26: =IFERROR(VLOOKUP(O26,Assumptions!$B$14:$C$26,2,FALSE()),"Other") -> Manager | AQ26: =IF(T26="",0,1) -> 1 | AR26: =IF(U26="",0,1) -> 1 | AS26: =IF(AK26="","",IF(MAX($AK$2:$AK$921)=MIN($AK$2:$AK$921),50,ROUND((AK26-MIN($AK$2:$AK$921))/(MAX($AK$2:$AK$921)-MIN($AK$2:$AK$921))*100,2))) -> 91.43 | AT26: =IF(MAX($BC$2:$BC$921)=MIN($BC$2:$BC$921),50,ROUND((BC26-MIN($BC$2:$BC$921))/(MAX($BC$2:$BC$921)-MIN($BC$2:$BC$921))*100,2)) -> 75 | AU26: =IF(MAX($BE$2:$BE$921)=MIN($BE$2:$BE$921),50,ROUND((BE26-MIN($BE$2:$BE$921))/(MAX($BE$2:$BE$921)-MIN($BE$2:$BE$921))*100,2)) -> 74.19 | AV26: =IF(MAX($AD$2:$AD$921)=MIN($AD$2:$AD$921),50,ROUND((AD26-MIN($AD$2:$AD$921))/(MAX($AD$2:$AD$921)-MIN($AD$2:$AD$921))*100,2)) -> 38.03 | AW26: =IF(MAX($AN$2:$AN$921)=MIN($AN$2:$AN$921),50,ROUND((AN26-MIN($AN$2:$AN$921))/(MAX($AN$2:$AN$921)-MIN($AN$2:$AN$921))*100,2)) -> 97.5 | AX26: =AQ26*100 -> 100 | AY26: =AR26*100 -> 100 | AZ26: =IFERROR(ROUND(AS26*Assumptions!$I$6+AW26*Assumptions!$I$7+AT26*Assumptions!$I$8+AU26*Assumptions!$I$9+AV26*Assumptions!$I$10+AX26*Assumptions!$I$11+AY26*Assumptions!$I$12,2),"") -> 83.11 | BA26: =IF(AZ26="","",IF(AZ26<=Assumptions!$I$18,"Below Expectation",IF(AZ26<=Assumptions!$I$19,"Developing",IF(AZ26<=Assumptions!$I$20,"Meets Expectation",IF(AZ26<=Assumptions!$I$21,"Exceeds","Star Performer"))))) -> Exceeds | BB26: =IF(AZ26="",0,IF(AZ26>=Assumptions!$I$26,1,0)) -> 1 | BC26: =IF(AL26="",2,AL26+2) -> 3 | BD26: =IF(AM26="",ROUND(AVERAGE($AM$2:$AM$921),3),AM26) -> 0.447 | BE26: =1-BD26 -> 0.553
A27: 8 | B27: 22114 | C27: IT Infrastructure | D27: Mr. Shashank S Pisat | E27: Collaboration Tools | F27: Chief - IT Infrastructure | G27: 24281819 | H27: Chief IT Infrastructure | I27: Bharat Bhushan | J27: Ms. Sudeshna Das | K27: Marrd. | L27: 35389 | M27: 51.10 | N27: 27242 | O27: Vice President | P27: Vice - President | Q27: 29.6 | R27: 1.11 | S27: 31.5 | T27: 42917 | U27: 44470 | V27: A+ | W27: A* | X27: A+ | Y27: A* | Z27: A* | AA27: Management Development Prog : Level - 1-Management-2008,Other Engineering Certificates-Communication-2003,Certificate Course-Information System-1998,Other Engineering Certificates-Novell Network-1996 | AB27: =IFERROR(VALUE(R27),0) -> 1.11 | AC27: =IFERROR(VALUE(M27),"") -> 51.1 | AD27: =IFERROR(VALUE(Q27),"") -> 29.6 | AE27: =IFERROR(VALUE(S27),"") -> 31.5 | AF27: =IF(V27="","",VLOOKUP(V27,Assumptions!$B$6:$C$9,2,FALSE())) -> 3 | AG27: =IF(W27="","",VLOOKUP(W27,Assumptions!$B$6:$C$9,2,FALSE())) -> 4 | AH27: =IF(X27="","",VLOOKUP(X27,Assumptions!$B$6:$C$9,2,FALSE())) -> 3 | AI27: =IF(Y27="","",VLOOKUP(Y27,Assumptions!$B$6:$C$9,2,FALSE())) -> 4 | AJ27: =IF(Z27="","",VLOOKUP(Z27,Assumptions!$B$6:$C$9,2,FALSE())) -> 4 | AK27: =IFERROR(ROUND(AVERAGE(AF27:AJ27),3),"") -> 3.6 | AL27: =IF(OR(AF27="",AJ27=""),"",AJ27-AF27) -> 1 | AM27: =IF(COUNT(AF27:AJ27)>=2,ROUND(_xlfn.STDEV.S(AF27:AJ27),3),"") -> 0.548 | AN27: =ROUND((IF(AF27="",0,AF27)*Assumptions!$F$15)+(IF(AG27="",0,AG27)*Assumptions!$F$16)+(IF(AH27="",0,AH27)*Assumptions!$F$17)+(IF(AI27="",0,AI27)*Assumptions!$F$18)+(IF(AJ27="",0,AJ27)*Assumptions!$F$19),3) -> 3.7 | AO27: =IF(AC27<=20,"",IF(AC27<=Assumptions!$F$6,"20-30",IF(AC27<=Assumptions!$F$7,"30-40",IF(AC27<=Assumptions!$F$8,"40-50",IF(AC27<=Assumptions!$F$9,"50-60",IF(AC27<=Assumptions!$F$10,"60+","")))))) -> 50-60 | AP27: =IFERROR(VLOOKUP(O27,Assumptions!$B$14:$C$26,2,FALSE()),"Other") -> Leadership | AQ27: =IF(T27="",0,1) -> 1 | AR27: =IF(U27="",0,1) -> 1 | AS27: =IF(AK27="","",IF(MAX($AK$2:$AK$921)=MIN($AK$2:$AK$921),50,ROUND((AK27-MIN($AK$2:$AK$921))/(MAX($AK$2:$AK$921)-MIN($AK$2:$AK$921))*100,2))) -> 82.85 | AT27: =IF(MAX($BC$2:$BC$921)=MIN($BC$2:$BC$921),50,ROUND((BC27-MIN($BC$2:$BC$921))/(MAX($BC$2:$BC$921)-MIN($BC$2:$BC$921))*100,2)) -> 75 | AU27: =IF(MAX($BE$2:$BE$921)=MIN($BE$2:$BE$921),50,ROUND((BE27-MIN($BE$2:$BE$921))/(MAX($BE$2:$BE$921)-MIN($BE$2:$BE$921))*100,2)) -> 68.36 | AV27: =IF(MAX($AD$2:$AD$921)=MIN($AD$2:$AD$921),50,ROUND((AD27-MIN($AD$2:$AD$921))/(MAX($AD$2:$AD$921)-MIN($AD$2:$AD$921))*100,2)) -> 80.16 | AW27: =IF(MAX($AN$2:$AN$921)=MIN($AN$2:$AN$921),50,ROUND((AN27-MIN($AN$2:$AN$921))/(MAX($AN$2:$AN$921)-MIN($AN$2:$AN$921))*100,2)) -> 92.5 | AX27: =AQ27*100 -> 100 | AY27: =AR27*100 -> 100 | AZ27: =IFERROR(ROUND(AS27*Assumptions!$I$6+AW27*Assumptions!$I$7+AT27*Assumptions!$I$8+AU27*Assumptions!$I$9+AV27*Assumptions!$I$10+AX27*Assumptions!$I$11+AY27*Assumptions!$I$12,2),"") -> 82.88 | BA27: =IF(AZ27="","",IF(AZ27<=Assumptions!$I$18,"Below Expectation",IF(AZ27<=Assumptions!$I$19,"Developing",IF(AZ27<=Assumptions!$I$20,"Meets Expectation",IF(AZ27<=Assumptions!$I$21,"Exceeds","Star Performer"))))) -> Exceeds | BB27: =IF(AZ27="",0,IF(AZ27>=Assumptions!$I$26,1,0)) -> 1 | BC27: =IF(AL27="",2,AL27+2) -> 3 | BD27: =IF(AM27="",ROUND(AVERAGE($AM$2:$AM$921),3),AM27) -> 0.548 | BE27: =1-BD27 -> 0.452
A28: 332 | B28: 19507440 | D28: Mr. Hiteshkumar Khatri | E28: HR Platform Development & Business Supp | F28: Lead Architect | G28: 24281722 | H28: Lead Architect | I28: Bharat Bhushan | J28: Mr. Hemant Jain | K28: Marrd. | L28: 37391 | M28: 47.6 | N28: 28814 | O28: DGM | P28: Dy. General Manager | Q28: 24 | R28: . | S28: 24.0 | T28: 38808 | U28: 44440 | V28: A* | W28: A+ | X28: A* | Y28: A* | Z28: A* | AA28: MBA-Human Resource-2008(PT),PGD in Computer Science-Information Science and Engg.-2002(PT),Certificate Course-Computer Management-2001,Certificate Course-Computer Applications-2000,BCom-Commerce-1999, | AB28: =IFERROR(VALUE(R28),0) -> 0 | AC28: =IFERROR(VALUE(M28),"") -> 47.6 | AD28: =IFERROR(VALUE(Q28),"") -> 24 | AE28: =IFERROR(VALUE(S28),"") -> 24 | AF28: =IF(V28="","",VLOOKUP(V28,Assumptions!$B$6:$C$9,2,FALSE())) -> 4 | AG28: =IF(W28="","",VLOOKUP(W28,Assumptions!$B$6:$C$9,2,FALSE())) -> 3 | AH28: =IF(X28="","",VLOOKUP(X28,Assumptions!$B$6:$C$9,2,FALSE())) -> 4 | AI28: =IF(Y28="","",VLOOKUP(Y28,Assumptions!$B$6:$C$9,2,FALSE())) -> 4 | AJ28: =IF(Z28="","",VLOOKUP(Z28,Assumptions!$B$6:$C$9,2,FALSE())) -> 4 | AK28: =IFERROR(ROUND(AVERAGE(AF28:AJ28),3),"") -> 3.8 | AL28: =IF(OR(AF28="",AJ28=""),"",AJ28-AF28) -> 0 | AM28: =IF(COUNT(AF28:AJ28)>=2,ROUND(_xlfn.STDEV.S(AF28:AJ28),3),"") -> 0.447 | AN28: =ROUND((IF(AF28="",0,AF28)*Assumptions!$F$15)+(IF(AG28="",0,AG28)*Assumptions!$F$16)+(IF(AH28="",0,AH28)*Assumptions!$F$17)+(IF(AI28="",0,AI28)*Assumptions!$F$18)+(IF(AJ28="",0,AJ28)*Assumptions!$F$19),3) -> 3.85 | AO28: =IF(AC28<=20,"",IF(AC28<=Assumptions!$F$6,"20-30",IF(AC28<=Assumptions!$F$7,"30-40",IF(AC28<=Assumptions!$F$8,"40-50",IF(AC28<=Assumptions!$F$9,"50-60",IF(AC28<=Assumptions!$F$10,"60+","")))))) -> 40-50 | AP28: =IFERROR(VLOOKUP(O28,Assumptions!$B$14:$C$26,2,FALSE()),"Other") -> Manager | AQ28: =IF(T28="",0,1) -> 1 | AR28: =IF(U28="",0,1) -> 1 | AS28: =IF(AK28="","",IF(MAX($AK$2:$AK$921)=MIN($AK$2:$AK$921),50,ROUND((AK28-MIN($AK$2:$AK$921))/(MAX($AK$2:$AK$921)-MIN($AK$2:$AK$921))*100,2))) -> 91.43 | AT28: =IF(MAX($BC$2:$BC$921)=MIN($BC$2:$BC$921),50,ROUND((BC28-MIN($BC$2:$BC$921))/(MAX($BC$2:$BC$921)-MIN($BC$2:$BC$921))*100,2)) -> 50 | AU28: =IF(MAX($BE$2:$BE$921)=MIN($BE$2:$BE$921),50,ROUND((BE28-MIN($BE$2:$BE$921))/(MAX($BE$2:$BE$921)-MIN($BE$2:$BE$921))*100,2)) -> 74.19 | AV28: =IF(MAX($AD$2:$AD$921)=MIN($AD$2:$AD$921),50,ROUND((AD28-MIN($AD$2:$AD$921))/(MAX($AD$2:$AD$921)-MIN($AD$2:$AD$921))*100,2)) -> 64.94 | AW28: =IF(MAX($AN$2:$AN$921)=MIN($AN$2:$AN$921),50,ROUND((AN28-MIN($AN$2:$AN$921))/(MAX($AN$2:$AN$921)-MIN($AN$2:$AN$921))*100,2)) -> 96.25 | AX28: =AQ28*100 -> 100 | AY28: =AR28*100 -> 100 | AZ28: =IFERROR(ROUND(AS28*Assumptions!$I$6+AW28*Assumptions!$I$7+AT28*Assumptions!$I$8+AU28*Assumptions!$I$9+AV28*Assumptions!$I$10+AX28*Assumptions!$I$11+AY28*Assumptions!$I$12,2),"") -> 81.8 | BA28: =IF(AZ28="","",IF(AZ28<=Assumptions!$I$18,"Below Expectation",IF(AZ28<=Assumptions!$I$19,"Developing",IF(AZ28<=Assumptions!$I$20,"Meets Expectation",IF(AZ28<=Assumptions!$I$21,"Exceeds","Star Performer"))))) -> Exceeds | BB28: =IF(AZ28="",0,IF(AZ28>=Assumptions!$I$26,1,0)) -> 1 | BC28: =IF(AL28="",2,AL28+2) -> 2 | BD28: =IF(AM28="",ROUND(AVERAGE($AM$2:$AM$921),3),AM28) -> 0.447 | BE28: =1-BD28 -> 0.553
